[2025-06-05T10:06:07.621+0000] {local_task_job_runner.py:120} INFO - ::group::Pre task execution logs
[2025-06-05T10:06:07.645+0000] {taskinstance.py:2076} INFO - Dependencies all met for dep_context=non-requeueable deps ti=<TaskInstance: crawl_dmcl_tara_dag.crawl_dmcl_prices manual__2025-06-05T10:06:05.999593+00:00 [queued]>
[2025-06-05T10:06:07.653+0000] {taskinstance.py:2076} INFO - Dependencies all met for dep_context=requeueable deps ti=<TaskInstance: crawl_dmcl_tara_dag.crawl_dmcl_prices manual__2025-06-05T10:06:05.999593+00:00 [queued]>
[2025-06-05T10:06:07.654+0000] {taskinstance.py:2306} INFO - Starting attempt 1 of 2
[2025-06-05T10:06:07.668+0000] {taskinstance.py:2330} INFO - Executing <Task(PythonOperator): crawl_dmcl_prices> on 2025-06-05 10:06:05.999593+00:00
[2025-06-05T10:06:07.673+0000] {standard_task_runner.py:63} INFO - Started process 177 to run task
[2025-06-05T10:06:07.676+0000] {standard_task_runner.py:90} INFO - Running: ['***', 'tasks', 'run', 'crawl_dmcl_tara_dag', 'crawl_dmcl_prices', 'manual__2025-06-05T10:06:05.999593+00:00', '--job-id', '172', '--raw', '--subdir', 'DAGS_FOLDER/dag_crawl_dmcl.py', '--cfg-path', '/tmp/tmpckpglrfw']
[2025-06-05T10:06:07.679+0000] {standard_task_runner.py:91} INFO - Job 172: Subtask crawl_dmcl_prices
[2025-06-05T10:06:07.729+0000] {task_command.py:426} INFO - Running <TaskInstance: crawl_dmcl_tara_dag.crawl_dmcl_prices manual__2025-06-05T10:06:05.999593+00:00 [running]> on host 93dd92a35e32
[2025-06-05T10:06:07.825+0000] {taskinstance.py:2648} INFO - Exporting env vars: AIRFLOW_CTX_DAG_OWNER='***' AIRFLOW_CTX_DAG_ID='crawl_dmcl_tara_dag' AIRFLOW_CTX_TASK_ID='crawl_dmcl_prices' AIRFLOW_CTX_EXECUTION_DATE='2025-06-05T10:06:05.999593+00:00' AIRFLOW_CTX_TRY_NUMBER='1' AIRFLOW_CTX_DAG_RUN_ID='manual__2025-06-05T10:06:05.999593+00:00'
[2025-06-05T10:06:07.826+0000] {taskinstance.py:430} INFO - ::endgroup::
[2025-06-05T10:06:09.799+0000] {taskinstance.py:441} INFO - ::group::Post task execution logs
[2025-06-05T10:06:09.800+0000] {taskinstance.py:2905} ERROR - Task failed with exception
Traceback (most recent call last):
  File "/usr/local/lib/python3.11/site-packages/airflow/models/taskinstance.py", line 465, in _execute_task
    result = _execute_callable(context=context, **execute_callable_kwargs)
             ^^^^^^^^^^^^^^^^^^^^^^^^^^^^^^^^^^^^^^^^^^^^^^^^^^^^^^^^^^^^^
  File "/usr/local/lib/python3.11/site-packages/airflow/models/taskinstance.py", line 432, in _execute_callable
    return execute_callable(context=context, **execute_callable_kwargs)
           ^^^^^^^^^^^^^^^^^^^^^^^^^^^^^^^^^^^^^^^^^^^^^^^^^^^^^^^^^^^^
  File "/usr/local/lib/python3.11/site-packages/airflow/models/baseoperator.py", line 400, in wrapper
    return func(self, *args, **kwargs)
           ^^^^^^^^^^^^^^^^^^^^^^^^^^^
  File "/usr/local/lib/python3.11/site-packages/airflow/operators/python.py", line 235, in execute
    return_value = self.execute_callable()
                   ^^^^^^^^^^^^^^^^^^^^^^^
  File "/usr/local/lib/python3.11/site-packages/airflow/operators/python.py", line 252, in execute_callable
    return self.python_callable(*self.op_args, **self.op_kwargs)
           ^^^^^^^^^^^^^^^^^^^^^^^^^^^^^^^^^^^^^^^^^^^^^^^^^^^^^
  File "/opt/airflow/dags/dag_crawl_dmcl.py", line 100, in crawl_dmcl_tara
    driver = webdriver.Chrome(options=chrome_options)
             ^^^^^^^^^^^^^^^^^^^^^^^^^^^^^^^^^^^^^^^^
  File "/usr/local/lib/python3.11/site-packages/selenium/webdriver/chrome/webdriver.py", line 47, in __init__
    super().__init__(
  File "/usr/local/lib/python3.11/site-packages/selenium/webdriver/chromium/webdriver.py", line 69, in __init__
    super().__init__(command_executor=executor, options=options)
  File "/usr/local/lib/python3.11/site-packages/selenium/webdriver/remote/webdriver.py", line 257, in __init__
    self.start_session(capabilities)
  File "/usr/local/lib/python3.11/site-packages/selenium/webdriver/remote/webdriver.py", line 356, in start_session
    response = self.execute(Command.NEW_SESSION, caps)["value"]
               ^^^^^^^^^^^^^^^^^^^^^^^^^^^^^^^^^^^^^^^
  File "/usr/local/lib/python3.11/site-packages/selenium/webdriver/remote/webdriver.py", line 447, in execute
    self.error_handler.check_response(response)
  File "/usr/local/lib/python3.11/site-packages/selenium/webdriver/remote/errorhandler.py", line 232, in check_response
    raise exception_class(message, screen, stacktrace)
selenium.common.exceptions.SessionNotCreatedException: Message: session not created: probably user data directory is already in use, please specify a unique value for --user-data-dir argument, or don't use --user-data-dir
Stacktrace:
#0 0x55622a05dd9e <unknown>
#1 0x556229afcfab <unknown>
#2 0x556229b3395a <unknown>
#3 0x556229b2ef5f <unknown>
#4 0x556229b83290 <unknown>
#5 0x556229b71283 <unknown>
#6 0x556229b3b0c9 <unknown>
#7 0x556229b3be78 <unknown>
#8 0x55622a029f5a <unknown>
#9 0x55622a02d3ae <unknown>
#10 0x55622a02ce58 <unknown>
#11 0x55622a02d845 <unknown>
#12 0x55622a01338b <unknown>
#13 0x55622a02dbb0 <unknown>
#14 0x556229ffc339 <unknown>
#15 0x55622a04c8b5 <unknown>
#16 0x55622a04ca9b <unknown>
#17 0x55622a05cf15 <unknown>
#18 0x7f7cc96fa1f5 <unknown>

[2025-06-05T10:06:09.818+0000] {taskinstance.py:1206} INFO - Marking task as UP_FOR_RETRY. dag_id=crawl_dmcl_tara_dag, task_id=crawl_dmcl_prices, run_id=manual__2025-06-05T10:06:05.999593+00:00, execution_date=20250605T100605, start_date=20250605T100607, end_date=20250605T100609
[2025-06-05T10:06:09.963+0000] {standard_task_runner.py:110} ERROR - Failed to execute job 172 for task crawl_dmcl_prices (Message: session not created: probably user data directory is already in use, please specify a unique value for --user-data-dir argument, or don't use --user-data-dir
Stacktrace:
#0 0x55622a05dd9e <unknown>
#1 0x556229afcfab <unknown>
#2 0x556229b3395a <unknown>
#3 0x556229b2ef5f <unknown>
#4 0x556229b83290 <unknown>
#5 0x556229b71283 <unknown>
#6 0x556229b3b0c9 <unknown>
#7 0x556229b3be78 <unknown>
#8 0x55622a029f5a <unknown>
#9 0x55622a02d3ae <unknown>
#10 0x55622a02ce58 <unknown>
#11 0x55622a02d845 <unknown>
#12 0x55622a01338b <unknown>
#13 0x55622a02dbb0 <unknown>
#14 0x556229ffc339 <unknown>
#15 0x55622a04c8b5 <unknown>
#16 0x55622a04ca9b <unknown>
#17 0x55622a05cf15 <unknown>
#18 0x7f7cc96fa1f5 <unknown>
; 177)
[2025-06-05T10:06:10.024+0000] {local_task_job_runner.py:240} INFO - Task exited with return code 1
[2025-06-05T10:06:10.044+0000] {taskinstance.py:3498} INFO - 0 downstream tasks scheduled from follow-on schedule check
[2025-06-05T10:06:10.046+0000] {local_task_job_runner.py:222} INFO - ::endgroup::
