[2025-06-05T07:28:59.887+0000] {local_task_job_runner.py:120} INFO - ::group::Pre task execution logs
[2025-06-05T07:28:59.912+0000] {taskinstance.py:2076} INFO - Dependencies all met for dep_context=non-requeueable deps ti=<TaskInstance: excel_to_postgres_test_data_dag.load_excel_data_to_postgres manual__2025-06-05T07:28:53.745986+00:00 [queued]>
[2025-06-05T07:28:59.919+0000] {taskinstance.py:2076} INFO - Dependencies all met for dep_context=requeueable deps ti=<TaskInstance: excel_to_postgres_test_data_dag.load_excel_data_to_postgres manual__2025-06-05T07:28:53.745986+00:00 [queued]>
[2025-06-05T07:28:59.919+0000] {taskinstance.py:2306} INFO - Starting attempt 1 of 1
[2025-06-05T07:28:59.932+0000] {taskinstance.py:2330} INFO - Executing <Task(PythonOperator): load_excel_data_to_postgres> on 2025-06-05 07:28:53.745986+00:00
[2025-06-05T07:28:59.935+0000] {standard_task_runner.py:63} INFO - Started process 35 to run task
[2025-06-05T07:28:59.938+0000] {standard_task_runner.py:90} INFO - Running: ['***', 'tasks', 'run', 'excel_to_postgres_test_data_dag', 'load_excel_data_to_postgres', 'manual__2025-06-05T07:28:53.745986+00:00', '--job-id', '159', '--raw', '--subdir', 'DAGS_FOLDER/excel_to_postgres_test_data_dag.py', '--cfg-path', '/tmp/tmpm80m8m1b']
[2025-06-05T07:28:59.941+0000] {standard_task_runner.py:91} INFO - Job 159: Subtask load_excel_data_to_postgres
[2025-06-05T07:28:59.985+0000] {task_command.py:426} INFO - Running <TaskInstance: excel_to_postgres_test_data_dag.load_excel_data_to_postgres manual__2025-06-05T07:28:53.745986+00:00 [running]> on host 7dd4bc557e5f
[2025-06-05T07:29:00.090+0000] {taskinstance.py:2648} INFO - Exporting env vars: AIRFLOW_CTX_DAG_OWNER='***' AIRFLOW_CTX_DAG_ID='excel_to_postgres_test_data_dag' AIRFLOW_CTX_TASK_ID='load_excel_data_to_postgres' AIRFLOW_CTX_EXECUTION_DATE='2025-06-05T07:28:53.745986+00:00' AIRFLOW_CTX_TRY_NUMBER='1' AIRFLOW_CTX_DAG_RUN_ID='manual__2025-06-05T07:28:53.745986+00:00'
[2025-06-05T07:29:00.092+0000] {taskinstance.py:430} INFO - ::endgroup::
[2025-06-05T07:29:05.480+0000] {taskinstance.py:441} INFO - ::group::Post task execution logs
[2025-06-05T07:29:05.906+0000] {taskinstance.py:2905} ERROR - Task failed with exception
Traceback (most recent call last):
  File "/usr/local/lib/python3.11/site-packages/airflow/models/taskinstance.py", line 465, in _execute_task
    result = _execute_callable(context=context, **execute_callable_kwargs)
             ^^^^^^^^^^^^^^^^^^^^^^^^^^^^^^^^^^^^^^^^^^^^^^^^^^^^^^^^^^^^^
  File "/usr/local/lib/python3.11/site-packages/airflow/models/taskinstance.py", line 432, in _execute_callable
    return execute_callable(context=context, **execute_callable_kwargs)
           ^^^^^^^^^^^^^^^^^^^^^^^^^^^^^^^^^^^^^^^^^^^^^^^^^^^^^^^^^^^^
  File "/usr/local/lib/python3.11/site-packages/airflow/models/baseoperator.py", line 400, in wrapper
    return func(self, *args, **kwargs)
           ^^^^^^^^^^^^^^^^^^^^^^^^^^^
  File "/usr/local/lib/python3.11/site-packages/airflow/operators/python.py", line 235, in execute
    return_value = self.execute_callable()
                   ^^^^^^^^^^^^^^^^^^^^^^^
  File "/usr/local/lib/python3.11/site-packages/airflow/operators/python.py", line 252, in execute_callable
    return self.python_callable(*self.op_args, **self.op_kwargs)
           ^^^^^^^^^^^^^^^^^^^^^^^^^^^^^^^^^^^^^^^^^^^^^^^^^^^^^
  File "/opt/airflow/dags/excel_to_postgres_test_data_dag.py", line 104, in load_excel_to_postgres
    conn = hook.get_conn()
           ^^^^^^^^^^^^^^^
  File "/usr/local/lib/python3.11/site-packages/airflow/providers/postgres/hooks/postgres.py", line 149, in get_conn
    conn = deepcopy(self.connection)
                    ^^^^^^^^^^^^^^^
  File "/usr/local/lib/python3.11/site-packages/airflow/providers/common/sql/hooks/sql.py", line 248, in connection
    self._connection = self.get_connection(self.get_conn_id())
                       ^^^^^^^^^^^^^^^^^^^^^^^^^^^^^^^^^^^^^^^
  File "/usr/local/lib/python3.11/site-packages/airflow/hooks/base.py", line 83, in get_connection
    conn = Connection.get_connection_from_secrets(conn_id)
           ^^^^^^^^^^^^^^^^^^^^^^^^^^^^^^^^^^^^^^^^^^^^^^^
  File "/usr/local/lib/python3.11/site-packages/airflow/models/connection.py", line 519, in get_connection_from_secrets
    raise AirflowNotFoundException(f"The conn_id `{conn_id}` isn't defined")
airflow.exceptions.AirflowNotFoundException: The conn_id `datalake_***` isn't defined
[2025-06-05T07:29:09.187+0000] {taskinstance.py:1206} INFO - Marking task as FAILED. dag_id=excel_to_postgres_test_data_dag, task_id=load_excel_data_to_postgres, run_id=manual__2025-06-05T07:28:53.745986+00:00, execution_date=20250605T072853, start_date=20250605T072859, end_date=20250605T072909
[2025-06-05T07:29:09.224+0000] {standard_task_runner.py:110} ERROR - Failed to execute job 159 for task load_excel_data_to_postgres (The conn_id `datalake_***` isn't defined; 35)
[2025-06-05T07:29:09.265+0000] {local_task_job_runner.py:240} INFO - Task exited with return code 1
[2025-06-05T07:29:09.289+0000] {taskinstance.py:3498} INFO - 0 downstream tasks scheduled from follow-on schedule check
[2025-06-05T07:29:09.293+0000] {local_task_job_runner.py:222} INFO - ::endgroup::
