[2025-06-05T02:20:57.830+0000] {local_task_job_runner.py:120} INFO - ::group::Pre task execution logs
[2025-06-05T02:20:57.853+0000] {taskinstance.py:2076} INFO - Dependencies all met for dep_context=non-requeueable deps ti=<TaskInstance: excel_to_postgres_test_data_dag.create_schema_and_table manual__2025-06-05T02:20:55.811379+00:00 [queued]>
[2025-06-05T02:20:57.860+0000] {taskinstance.py:2076} INFO - Dependencies all met for dep_context=requeueable deps ti=<TaskInstance: excel_to_postgres_test_data_dag.create_schema_and_table manual__2025-06-05T02:20:55.811379+00:00 [queued]>
[2025-06-05T02:20:57.861+0000] {taskinstance.py:2306} INFO - Starting attempt 1 of 1
[2025-06-05T02:20:57.876+0000] {taskinstance.py:2330} INFO - Executing <Task(PythonOperator): create_schema_and_table> on 2025-06-05 02:20:55.811379+00:00
[2025-06-05T02:20:57.880+0000] {standard_task_runner.py:63} INFO - Started process 32 to run task
[2025-06-05T02:20:57.883+0000] {standard_task_runner.py:90} INFO - Running: ['***', 'tasks', 'run', 'excel_to_postgres_test_data_dag', 'create_schema_and_table', 'manual__2025-06-05T02:20:55.811379+00:00', '--job-id', '155', '--raw', '--subdir', 'DAGS_FOLDER/excel_to_postgres_test_data_dag.py', '--cfg-path', '/tmp/tmp0xdr6l4q']
[2025-06-05T02:20:57.886+0000] {standard_task_runner.py:91} INFO - Job 155: Subtask create_schema_and_table
[2025-06-05T02:20:58.208+0000] {task_command.py:426} INFO - Running <TaskInstance: excel_to_postgres_test_data_dag.create_schema_and_table manual__2025-06-05T02:20:55.811379+00:00 [running]> on host 70d97023b80f
[2025-06-05T02:20:58.743+0000] {taskinstance.py:2648} INFO - Exporting env vars: AIRFLOW_CTX_DAG_OWNER='***' AIRFLOW_CTX_DAG_ID='excel_to_postgres_test_data_dag' AIRFLOW_CTX_TASK_ID='create_schema_and_table' AIRFLOW_CTX_EXECUTION_DATE='2025-06-05T02:20:55.811379+00:00' AIRFLOW_CTX_TRY_NUMBER='1' AIRFLOW_CTX_DAG_RUN_ID='manual__2025-06-05T02:20:55.811379+00:00'
[2025-06-05T02:20:58.744+0000] {taskinstance.py:430} INFO - ::endgroup::
[2025-06-05T02:20:58.773+0000] {base.py:84} INFO - Using connection ID 'datalake_***' for task execution.
[2025-06-05T02:21:19.817+0000] {taskinstance.py:441} INFO - ::group::Post task execution logs
[2025-06-05T02:21:19.818+0000] {taskinstance.py:2905} ERROR - Task failed with exception
Traceback (most recent call last):
  File "/usr/local/lib/python3.11/site-packages/airflow/models/taskinstance.py", line 465, in _execute_task
    result = _execute_callable(context=context, **execute_callable_kwargs)
             ^^^^^^^^^^^^^^^^^^^^^^^^^^^^^^^^^^^^^^^^^^^^^^^^^^^^^^^^^^^^^
  File "/usr/local/lib/python3.11/site-packages/airflow/models/taskinstance.py", line 432, in _execute_callable
    return execute_callable(context=context, **execute_callable_kwargs)
           ^^^^^^^^^^^^^^^^^^^^^^^^^^^^^^^^^^^^^^^^^^^^^^^^^^^^^^^^^^^^
  File "/usr/local/lib/python3.11/site-packages/airflow/models/baseoperator.py", line 400, in wrapper
    return func(self, *args, **kwargs)
           ^^^^^^^^^^^^^^^^^^^^^^^^^^^
  File "/usr/local/lib/python3.11/site-packages/airflow/operators/python.py", line 235, in execute
    return_value = self.execute_callable()
                   ^^^^^^^^^^^^^^^^^^^^^^^
  File "/usr/local/lib/python3.11/site-packages/airflow/operators/python.py", line 252, in execute_callable
    return self.python_callable(*self.op_args, **self.op_kwargs)
           ^^^^^^^^^^^^^^^^^^^^^^^^^^^^^^^^^^^^^^^^^^^^^^^^^^^^^
  File "/opt/airflow/dags/excel_to_postgres_test_data_dag.py", line 13, in create_schema_and_table
    conn = hook.get_conn()
           ^^^^^^^^^^^^^^^
  File "/usr/local/lib/python3.11/site-packages/airflow/providers/postgres/hooks/postgres.py", line 173, in get_conn
    self.conn = psycopg2.connect(**conn_args)
                ^^^^^^^^^^^^^^^^^^^^^^^^^^^^^
  File "/usr/local/lib/python3.11/site-packages/psycopg2/__init__.py", line 122, in connect
    conn = _connect(dsn, connection_factory=connection_factory, **kwasync)
           ^^^^^^^^^^^^^^^^^^^^^^^^^^^^^^^^^^^^^^^^^^^^^^^^^^^^^^^^^^^^^^^
psycopg2.OperationalError: connection to server at "172.16.0.55", port 5432 failed: Connection refused
	Is the server running on that host and accepting TCP/IP connections?

[2025-06-05T02:21:24.013+0000] {taskinstance.py:1206} INFO - Marking task as FAILED. dag_id=excel_to_postgres_test_data_dag, task_id=create_schema_and_table, run_id=manual__2025-06-05T02:20:55.811379+00:00, execution_date=20250605T022055, start_date=20250605T022057, end_date=20250605T022124
[2025-06-05T02:21:24.043+0000] {standard_task_runner.py:110} ERROR - Failed to execute job 155 for task create_schema_and_table (connection to server at "172.16.0.55", port 5432 failed: Connection refused
	Is the server running on that host and accepting TCP/IP connections?
; 32)
[2025-06-05T02:21:24.063+0000] {local_task_job_runner.py:240} INFO - Task exited with return code 1
[2025-06-05T02:21:24.083+0000] {taskinstance.py:3498} INFO - 0 downstream tasks scheduled from follow-on schedule check
[2025-06-05T02:21:24.087+0000] {local_task_job_runner.py:222} INFO - ::endgroup::
