[2025-06-09T02:46:13.506+0000] {local_task_job_runner.py:120} INFO - ::group::Pre task execution logs
[2025-06-09T02:46:13.534+0000] {taskinstance.py:2076} INFO - Dependencies all met for dep_context=non-requeueable deps ti=<TaskInstance: crawl_dcml_and_upload_2datalake_dag.crawl_dmcl manual__2025-06-09T02:37:39.574511+00:00 [queued]>
[2025-06-09T02:46:13.545+0000] {taskinstance.py:2076} INFO - Dependencies all met for dep_context=requeueable deps ti=<TaskInstance: crawl_dcml_and_upload_2datalake_dag.crawl_dmcl manual__2025-06-09T02:37:39.574511+00:00 [queued]>
[2025-06-09T02:46:13.546+0000] {taskinstance.py:2306} INFO - Starting attempt 2 of 2
[2025-06-09T02:46:13.562+0000] {taskinstance.py:2330} INFO - Executing <Task(PythonOperator): crawl_dmcl> on 2025-06-09 02:37:39.574511+00:00
[2025-06-09T02:46:13.568+0000] {standard_task_runner.py:63} INFO - Started process 368 to run task
[2025-06-09T02:46:13.571+0000] {standard_task_runner.py:90} INFO - Running: ['***', 'tasks', 'run', 'crawl_dcml_and_upload_2datalake_dag', 'crawl_dmcl', 'manual__2025-06-09T02:37:39.574511+00:00', '--job-id', '183', '--raw', '--subdir', 'DAGS_FOLDER/dag_crawl_dmcl_load2datalake.py', '--cfg-path', '/tmp/tmp07mogkd6']
[2025-06-09T02:46:13.574+0000] {standard_task_runner.py:91} INFO - Job 183: Subtask crawl_dmcl
[2025-06-09T02:46:13.628+0000] {task_command.py:426} INFO - Running <TaskInstance: crawl_dcml_and_upload_2datalake_dag.crawl_dmcl manual__2025-06-09T02:37:39.574511+00:00 [running]> on host 6b5241449da9
[2025-06-09T02:46:13.714+0000] {taskinstance.py:2648} INFO - Exporting env vars: AIRFLOW_CTX_DAG_OWNER='***' AIRFLOW_CTX_DAG_ID='crawl_dcml_and_upload_2datalake_dag' AIRFLOW_CTX_TASK_ID='crawl_dmcl' AIRFLOW_CTX_EXECUTION_DATE='2025-06-09T02:37:39.574511+00:00' AIRFLOW_CTX_TRY_NUMBER='2' AIRFLOW_CTX_DAG_RUN_ID='manual__2025-06-09T02:37:39.574511+00:00'
[2025-06-09T02:46:13.715+0000] {taskinstance.py:430} INFO - ::endgroup::
[2025-06-09T02:49:46.317+0000] {taskinstance.py:441} INFO - ::group::Post task execution logs
[2025-06-09T02:49:46.344+0000] {taskinstance.py:2905} ERROR - Task failed with exception
Traceback (most recent call last):
  File "/usr/local/lib/python3.11/site-packages/airflow/models/taskinstance.py", line 465, in _execute_task
    result = _execute_callable(context=context, **execute_callable_kwargs)
             ^^^^^^^^^^^^^^^^^^^^^^^^^^^^^^^^^^^^^^^^^^^^^^^^^^^^^^^^^^^^^
  File "/usr/local/lib/python3.11/site-packages/airflow/models/taskinstance.py", line 432, in _execute_callable
    return execute_callable(context=context, **execute_callable_kwargs)
           ^^^^^^^^^^^^^^^^^^^^^^^^^^^^^^^^^^^^^^^^^^^^^^^^^^^^^^^^^^^^
  File "/usr/local/lib/python3.11/site-packages/airflow/models/baseoperator.py", line 400, in wrapper
    return func(self, *args, **kwargs)
           ^^^^^^^^^^^^^^^^^^^^^^^^^^^
  File "/usr/local/lib/python3.11/site-packages/airflow/operators/python.py", line 235, in execute
    return_value = self.execute_callable()
                   ^^^^^^^^^^^^^^^^^^^^^^^
  File "/usr/local/lib/python3.11/site-packages/airflow/operators/python.py", line 252, in execute_callable
    return self.python_callable(*self.op_args, **self.op_kwargs)
           ^^^^^^^^^^^^^^^^^^^^^^^^^^^^^^^^^^^^^^^^^^^^^^^^^^^^^
  File "/opt/airflow/dags/dag_crawl_dmcl_load2datalake.py", line 118, in crawl_dmcl
    df.to_excel("./db/results/tara/dmcl_tara.xlsx", index=False, engine="openpyxl", sheet_name="follow_price_dmcl")
  File "/usr/local/lib/python3.11/site-packages/pandas/util/_decorators.py", line 333, in wrapper
    return func(*args, **kwargs)
           ^^^^^^^^^^^^^^^^^^^^^
  File "/usr/local/lib/python3.11/site-packages/pandas/core/generic.py", line 2436, in to_excel
    formatter.write(
  File "/usr/local/lib/python3.11/site-packages/pandas/io/formats/excel.py", line 943, in write
    writer = ExcelWriter(
             ^^^^^^^^^^^^
  File "/usr/local/lib/python3.11/site-packages/pandas/io/excel/_openpyxl.py", line 61, in __init__
    super().__init__(
  File "/usr/local/lib/python3.11/site-packages/pandas/io/excel/_base.py", line 1246, in __init__
    self._handles = get_handle(
                    ^^^^^^^^^^^
  File "/usr/local/lib/python3.11/site-packages/pandas/io/common.py", line 882, in get_handle
    handle = open(handle, ioargs.mode)
             ^^^^^^^^^^^^^^^^^^^^^^^^^
PermissionError: [Errno 13] Permission denied: './db/results/tara/dmcl_tara.xlsx'
[2025-06-09T02:49:46.697+0000] {taskinstance.py:1206} INFO - Marking task as FAILED. dag_id=crawl_dcml_and_upload_2datalake_dag, task_id=crawl_dmcl, run_id=manual__2025-06-09T02:37:39.574511+00:00, execution_date=20250609T023739, start_date=20250609T024613, end_date=20250609T024946
[2025-06-09T02:49:46.769+0000] {standard_task_runner.py:110} ERROR - Failed to execute job 183 for task crawl_dmcl ([Errno 13] Permission denied: './db/results/tara/dmcl_tara.xlsx'; 368)
[2025-06-09T02:49:46.807+0000] {local_task_job_runner.py:240} INFO - Task exited with return code 1
[2025-06-09T02:49:46.892+0000] {taskinstance.py:3498} INFO - 0 downstream tasks scheduled from follow-on schedule check
[2025-06-09T02:49:46.899+0000] {local_task_job_runner.py:222} INFO - ::endgroup::
