[2025-06-04T10:23:18.414+0000] {local_task_job_runner.py:120} INFO - ::group::Pre task execution logs
[2025-06-04T10:23:18.436+0000] {taskinstance.py:2076} INFO - Dependencies all met for dep_context=non-requeueable deps ti=<TaskInstance: excel_to_postgres_test_data_dag.load_excel_data_to_postgres manual__2025-06-04T10:23:12.286991+00:00 [queued]>
[2025-06-04T10:23:18.447+0000] {taskinstance.py:2076} INFO - Dependencies all met for dep_context=requeueable deps ti=<TaskInstance: excel_to_postgres_test_data_dag.load_excel_data_to_postgres manual__2025-06-04T10:23:12.286991+00:00 [queued]>
[2025-06-04T10:23:18.447+0000] {taskinstance.py:2306} INFO - Starting attempt 1 of 1
[2025-06-04T10:23:18.461+0000] {taskinstance.py:2330} INFO - Executing <Task(PythonOperator): load_excel_data_to_postgres> on 2025-06-04 10:23:12.286991+00:00
[2025-06-04T10:23:18.465+0000] {standard_task_runner.py:63} INFO - Started process 36 to run task
[2025-06-04T10:23:18.467+0000] {standard_task_runner.py:90} INFO - Running: ['***', 'tasks', 'run', 'excel_to_postgres_test_data_dag', 'load_excel_data_to_postgres', 'manual__2025-06-04T10:23:12.286991+00:00', '--job-id', '151', '--raw', '--subdir', 'DAGS_FOLDER/excel_to_postgres_test_data_dag.py', '--cfg-path', '/tmp/tmpdn6a19c9']
[2025-06-04T10:23:18.470+0000] {standard_task_runner.py:91} INFO - Job 151: Subtask load_excel_data_to_postgres
[2025-06-04T10:23:18.511+0000] {task_command.py:426} INFO - Running <TaskInstance: excel_to_postgres_test_data_dag.load_excel_data_to_postgres manual__2025-06-04T10:23:12.286991+00:00 [running]> on host 70d97023b80f
[2025-06-04T10:23:18.586+0000] {taskinstance.py:2648} INFO - Exporting env vars: AIRFLOW_CTX_DAG_OWNER='***' AIRFLOW_CTX_DAG_ID='excel_to_postgres_test_data_dag' AIRFLOW_CTX_TASK_ID='load_excel_data_to_postgres' AIRFLOW_CTX_EXECUTION_DATE='2025-06-04T10:23:12.286991+00:00' AIRFLOW_CTX_TRY_NUMBER='1' AIRFLOW_CTX_DAG_RUN_ID='manual__2025-06-04T10:23:12.286991+00:00'
[2025-06-04T10:23:18.587+0000] {taskinstance.py:430} INFO - ::endgroup::
[2025-06-04T10:23:18.893+0000] {base.py:84} INFO - Using connection ID 'datalake_***' for task execution.
[2025-06-04T10:23:18.903+0000] {warnings.py:110} WARNING - /opt/***/dags/excel_to_postgres_test_data_dag.py:66: UserWarning: pandas only supports SQLAlchemy connectable (engine/connection) or database string URI or sqlite3 DBAPI2 connection. Other DBAPI2 objects are not tested. Please consider using SQLAlchemy.
  df.to_sql(

[2025-06-04T10:23:18.906+0000] {taskinstance.py:441} INFO - ::group::Post task execution logs
[2025-06-04T10:23:18.908+0000] {taskinstance.py:2905} ERROR - Task failed with exception
Traceback (most recent call last):
  File "/usr/local/lib/python3.11/site-packages/airflow/models/taskinstance.py", line 465, in _execute_task
    result = _execute_callable(context=context, **execute_callable_kwargs)
             ^^^^^^^^^^^^^^^^^^^^^^^^^^^^^^^^^^^^^^^^^^^^^^^^^^^^^^^^^^^^^
  File "/usr/local/lib/python3.11/site-packages/airflow/models/taskinstance.py", line 432, in _execute_callable
    return execute_callable(context=context, **execute_callable_kwargs)
           ^^^^^^^^^^^^^^^^^^^^^^^^^^^^^^^^^^^^^^^^^^^^^^^^^^^^^^^^^^^^
  File "/usr/local/lib/python3.11/site-packages/airflow/models/baseoperator.py", line 400, in wrapper
    return func(self, *args, **kwargs)
           ^^^^^^^^^^^^^^^^^^^^^^^^^^^
  File "/usr/local/lib/python3.11/site-packages/airflow/operators/python.py", line 235, in execute
    return_value = self.execute_callable()
                   ^^^^^^^^^^^^^^^^^^^^^^^
  File "/usr/local/lib/python3.11/site-packages/airflow/operators/python.py", line 252, in execute_callable
    return self.python_callable(*self.op_args, **self.op_kwargs)
           ^^^^^^^^^^^^^^^^^^^^^^^^^^^^^^^^^^^^^^^^^^^^^^^^^^^^^
  File "/opt/airflow/dags/excel_to_postgres_test_data_dag.py", line 66, in load_excel_to_postgres
    df.to_sql(
  File "/usr/local/lib/python3.11/site-packages/pandas/util/_decorators.py", line 333, in wrapper
    return func(*args, **kwargs)
           ^^^^^^^^^^^^^^^^^^^^^
  File "/usr/local/lib/python3.11/site-packages/pandas/core/generic.py", line 3087, in to_sql
    return sql.to_sql(
           ^^^^^^^^^^^
  File "/usr/local/lib/python3.11/site-packages/pandas/io/sql.py", line 842, in to_sql
    return pandas_sql.to_sql(
           ^^^^^^^^^^^^^^^^^^
  File "/usr/local/lib/python3.11/site-packages/pandas/io/sql.py", line 2850, in to_sql
    table.create()
  File "/usr/local/lib/python3.11/site-packages/pandas/io/sql.py", line 984, in create
    if self.exists():
       ^^^^^^^^^^^^^
  File "/usr/local/lib/python3.11/site-packages/pandas/io/sql.py", line 970, in exists
    return self.pd_sql.has_table(self.name, self.schema)
           ^^^^^^^^^^^^^^^^^^^^^^^^^^^^^^^^^^^^^^^^^^^^^
  File "/usr/local/lib/python3.11/site-packages/pandas/io/sql.py", line 2865, in has_table
    return len(self.execute(query, [name]).fetchall()) > 0
               ^^^^^^^^^^^^^^^^^^^^^^^^^^^
  File "/usr/local/lib/python3.11/site-packages/pandas/io/sql.py", line 2672, in execute
    cur = self.con.cursor()
          ^^^^^^^^^^^^^^^
AttributeError: 'Engine' object has no attribute 'cursor'
[2025-06-04T10:23:18.926+0000] {taskinstance.py:1206} INFO - Marking task as FAILED. dag_id=excel_to_postgres_test_data_dag, task_id=load_excel_data_to_postgres, run_id=manual__2025-06-04T10:23:12.286991+00:00, execution_date=20250604T102312, start_date=20250604T102318, end_date=20250604T102318
[2025-06-04T10:23:18.943+0000] {standard_task_runner.py:110} ERROR - Failed to execute job 151 for task load_excel_data_to_postgres ('Engine' object has no attribute 'cursor'; 36)
[2025-06-04T10:23:18.960+0000] {local_task_job_runner.py:240} INFO - Task exited with return code 1
[2025-06-04T10:23:18.976+0000] {taskinstance.py:3498} INFO - 0 downstream tasks scheduled from follow-on schedule check
[2025-06-04T10:23:18.983+0000] {local_task_job_runner.py:222} INFO - ::endgroup::
