[2025-06-05T11:21:29.065+0000] {local_task_job_runner.py:120} INFO - ::group::Pre task execution logs
[2025-06-05T11:21:29.089+0000] {taskinstance.py:2076} INFO - Dependencies all met for dep_context=non-requeueable deps ti=<TaskInstance: upload_to_datalake_dag.upload_to_product_price manual__2025-06-05T11:16:22.985364+00:00 [queued]>
[2025-06-05T11:21:29.096+0000] {taskinstance.py:2076} INFO - Dependencies all met for dep_context=requeueable deps ti=<TaskInstance: upload_to_datalake_dag.upload_to_product_price manual__2025-06-05T11:16:22.985364+00:00 [queued]>
[2025-06-05T11:21:29.096+0000] {taskinstance.py:2306} INFO - Starting attempt 2 of 2
[2025-06-05T11:21:29.110+0000] {taskinstance.py:2330} INFO - Executing <Task(PythonOperator): upload_to_product_price> on 2025-06-05 11:16:22.985364+00:00
[2025-06-05T11:21:29.115+0000] {standard_task_runner.py:63} INFO - Started process 35 to run task
[2025-06-05T11:21:29.118+0000] {standard_task_runner.py:90} INFO - Running: ['***', 'tasks', 'run', 'upload_to_datalake_dag', 'upload_to_product_price', 'manual__2025-06-05T11:16:22.985364+00:00', '--job-id', '177', '--raw', '--subdir', 'DAGS_FOLDER/dag_2datalake_from_crawl_dmcl.py', '--cfg-path', '/tmp/tmpjqqri54y']
[2025-06-05T11:21:29.121+0000] {standard_task_runner.py:91} INFO - Job 177: Subtask upload_to_product_price
[2025-06-05T11:21:29.167+0000] {task_command.py:426} INFO - Running <TaskInstance: upload_to_datalake_dag.upload_to_product_price manual__2025-06-05T11:16:22.985364+00:00 [running]> on host 547795a17871
[2025-06-05T11:21:29.250+0000] {taskinstance.py:2648} INFO - Exporting env vars: AIRFLOW_CTX_DAG_OWNER='***' AIRFLOW_CTX_DAG_ID='upload_to_datalake_dag' AIRFLOW_CTX_TASK_ID='upload_to_product_price' AIRFLOW_CTX_EXECUTION_DATE='2025-06-05T11:16:22.985364+00:00' AIRFLOW_CTX_TRY_NUMBER='2' AIRFLOW_CTX_DAG_RUN_ID='manual__2025-06-05T11:16:22.985364+00:00'
[2025-06-05T11:21:29.251+0000] {taskinstance.py:430} INFO - ::endgroup::
[2025-06-05T11:21:30.181+0000] {dag_2datalake_from_crawl_dmcl.py:116} ERROR - Error occurred: "['nav_code', 'category'] not in index"
[2025-06-05T11:21:30.182+0000] {taskinstance.py:441} INFO - ::group::Post task execution logs
[2025-06-05T11:21:30.183+0000] {taskinstance.py:2905} ERROR - Task failed with exception
Traceback (most recent call last):
  File "/usr/local/lib/python3.11/site-packages/airflow/models/taskinstance.py", line 465, in _execute_task
    result = _execute_callable(context=context, **execute_callable_kwargs)
             ^^^^^^^^^^^^^^^^^^^^^^^^^^^^^^^^^^^^^^^^^^^^^^^^^^^^^^^^^^^^^
  File "/usr/local/lib/python3.11/site-packages/airflow/models/taskinstance.py", line 432, in _execute_callable
    return execute_callable(context=context, **execute_callable_kwargs)
           ^^^^^^^^^^^^^^^^^^^^^^^^^^^^^^^^^^^^^^^^^^^^^^^^^^^^^^^^^^^^
  File "/usr/local/lib/python3.11/site-packages/airflow/models/baseoperator.py", line 400, in wrapper
    return func(self, *args, **kwargs)
           ^^^^^^^^^^^^^^^^^^^^^^^^^^^
  File "/usr/local/lib/python3.11/site-packages/airflow/operators/python.py", line 235, in execute
    return_value = self.execute_callable()
                   ^^^^^^^^^^^^^^^^^^^^^^^
  File "/usr/local/lib/python3.11/site-packages/airflow/operators/python.py", line 252, in execute_callable
    return self.python_callable(*self.op_args, **self.op_kwargs)
           ^^^^^^^^^^^^^^^^^^^^^^^^^^^^^^^^^^^^^^^^^^^^^^^^^^^^^
  File "/opt/airflow/dags/dag_2datalake_from_crawl_dmcl.py", line 96, in upload_to_datalake
    df_raw = get_raw_data()
             ^^^^^^^^^^^^^^
  File "/opt/airflow/dags/dag_2datalake_from_crawl_dmcl.py", line 31, in get_raw_data
    return df[['MODEL', 'CP', 'nav_code', 'category']]
           ~~^^^^^^^^^^^^^^^^^^^^^^^^^^^^^^^^^^^^^^^^^
  File "/usr/local/lib/python3.11/site-packages/pandas/core/frame.py", line 4113, in __getitem__
    indexer = self.columns._get_indexer_strict(key, "columns")[1]
              ^^^^^^^^^^^^^^^^^^^^^^^^^^^^^^^^^^^^^^^^^^^^^^^^
  File "/usr/local/lib/python3.11/site-packages/pandas/core/indexes/base.py", line 6212, in _get_indexer_strict
    self._raise_if_missing(keyarr, indexer, axis_name)
  File "/usr/local/lib/python3.11/site-packages/pandas/core/indexes/base.py", line 6264, in _raise_if_missing
    raise KeyError(f"{not_found} not in index")
KeyError: "['nav_code', 'category'] not in index"
[2025-06-05T11:21:30.201+0000] {taskinstance.py:1206} INFO - Marking task as FAILED. dag_id=upload_to_datalake_dag, task_id=upload_to_product_price, run_id=manual__2025-06-05T11:16:22.985364+00:00, execution_date=20250605T111622, start_date=20250605T112129, end_date=20250605T112130
[2025-06-05T11:21:30.213+0000] {standard_task_runner.py:110} ERROR - Failed to execute job 177 for task upload_to_product_price ("['nav_code', 'category'] not in index"; 35)
[2025-06-05T11:21:30.254+0000] {local_task_job_runner.py:240} INFO - Task exited with return code 1
[2025-06-05T11:21:30.270+0000] {taskinstance.py:3498} INFO - 0 downstream tasks scheduled from follow-on schedule check
[2025-06-05T11:21:30.273+0000] {local_task_job_runner.py:222} INFO - ::endgroup::
