[2025-06-05T10:03:53.506+0000] {local_task_job_runner.py:120} INFO - ::group::Pre task execution logs
[2025-06-05T10:03:53.534+0000] {taskinstance.py:2076} INFO - Dependencies all met for dep_context=non-requeueable deps ti=<TaskInstance: crawl_dmcl_tara_dag.crawl_dmcl_prices manual__2025-06-05T09:58:44.801779+00:00 [queued]>
[2025-06-05T10:03:53.545+0000] {taskinstance.py:2076} INFO - Dependencies all met for dep_context=requeueable deps ti=<TaskInstance: crawl_dmcl_tara_dag.crawl_dmcl_prices manual__2025-06-05T09:58:44.801779+00:00 [queued]>
[2025-06-05T10:03:53.545+0000] {taskinstance.py:2306} INFO - Starting attempt 2 of 2
[2025-06-05T10:03:53.564+0000] {taskinstance.py:2330} INFO - Executing <Task(PythonOperator): crawl_dmcl_prices> on 2025-06-05 09:58:44.801779+00:00
[2025-06-05T10:03:53.574+0000] {standard_task_runner.py:63} INFO - Started process 110 to run task
[2025-06-05T10:03:53.583+0000] {standard_task_runner.py:90} INFO - Running: ['***', 'tasks', 'run', 'crawl_dmcl_tara_dag', 'crawl_dmcl_prices', 'manual__2025-06-05T09:58:44.801779+00:00', '--job-id', '171', '--raw', '--subdir', 'DAGS_FOLDER/dag_crawl_dmcl.py', '--cfg-path', '/tmp/tmp8azvjcjk']
[2025-06-05T10:03:53.625+0000] {standard_task_runner.py:91} INFO - Job 171: Subtask crawl_dmcl_prices
[2025-06-05T10:03:53.780+0000] {task_command.py:426} INFO - Running <TaskInstance: crawl_dmcl_tara_dag.crawl_dmcl_prices manual__2025-06-05T09:58:44.801779+00:00 [running]> on host 93dd92a35e32
[2025-06-05T10:03:53.916+0000] {taskinstance.py:2648} INFO - Exporting env vars: AIRFLOW_CTX_DAG_OWNER='***' AIRFLOW_CTX_DAG_ID='crawl_dmcl_tara_dag' AIRFLOW_CTX_TASK_ID='crawl_dmcl_prices' AIRFLOW_CTX_EXECUTION_DATE='2025-06-05T09:58:44.801779+00:00' AIRFLOW_CTX_TRY_NUMBER='2' AIRFLOW_CTX_DAG_RUN_ID='manual__2025-06-05T09:58:44.801779+00:00'
[2025-06-05T10:03:53.918+0000] {taskinstance.py:430} INFO - ::endgroup::
[2025-06-05T10:03:55.513+0000] {taskinstance.py:441} INFO - ::group::Post task execution logs
[2025-06-05T10:03:55.513+0000] {taskinstance.py:2905} ERROR - Task failed with exception
Traceback (most recent call last):
  File "/usr/local/lib/python3.11/site-packages/airflow/models/taskinstance.py", line 465, in _execute_task
    result = _execute_callable(context=context, **execute_callable_kwargs)
             ^^^^^^^^^^^^^^^^^^^^^^^^^^^^^^^^^^^^^^^^^^^^^^^^^^^^^^^^^^^^^
  File "/usr/local/lib/python3.11/site-packages/airflow/models/taskinstance.py", line 432, in _execute_callable
    return execute_callable(context=context, **execute_callable_kwargs)
           ^^^^^^^^^^^^^^^^^^^^^^^^^^^^^^^^^^^^^^^^^^^^^^^^^^^^^^^^^^^^
  File "/usr/local/lib/python3.11/site-packages/airflow/models/baseoperator.py", line 400, in wrapper
    return func(self, *args, **kwargs)
           ^^^^^^^^^^^^^^^^^^^^^^^^^^^
  File "/usr/local/lib/python3.11/site-packages/airflow/operators/python.py", line 235, in execute
    return_value = self.execute_callable()
                   ^^^^^^^^^^^^^^^^^^^^^^^
  File "/usr/local/lib/python3.11/site-packages/airflow/operators/python.py", line 252, in execute_callable
    return self.python_callable(*self.op_args, **self.op_kwargs)
           ^^^^^^^^^^^^^^^^^^^^^^^^^^^^^^^^^^^^^^^^^^^^^^^^^^^^^
  File "/opt/airflow/dags/dag_crawl_dmcl.py", line 95, in crawl_dmcl_tara
    driver = webdriver.Chrome(options=chrome_options)
             ^^^^^^^^^^^^^^^^^^^^^^^^^^^^^^^^^^^^^^^^
  File "/usr/local/lib/python3.11/site-packages/selenium/webdriver/chrome/webdriver.py", line 47, in __init__
    super().__init__(
  File "/usr/local/lib/python3.11/site-packages/selenium/webdriver/chromium/webdriver.py", line 69, in __init__
    super().__init__(command_executor=executor, options=options)
  File "/usr/local/lib/python3.11/site-packages/selenium/webdriver/remote/webdriver.py", line 257, in __init__
    self.start_session(capabilities)
  File "/usr/local/lib/python3.11/site-packages/selenium/webdriver/remote/webdriver.py", line 356, in start_session
    response = self.execute(Command.NEW_SESSION, caps)["value"]
               ^^^^^^^^^^^^^^^^^^^^^^^^^^^^^^^^^^^^^^^
  File "/usr/local/lib/python3.11/site-packages/selenium/webdriver/remote/webdriver.py", line 447, in execute
    self.error_handler.check_response(response)
  File "/usr/local/lib/python3.11/site-packages/selenium/webdriver/remote/errorhandler.py", line 232, in check_response
    raise exception_class(message, screen, stacktrace)
selenium.common.exceptions.SessionNotCreatedException: Message: session not created: probably user data directory is already in use, please specify a unique value for --user-data-dir argument, or don't use --user-data-dir
Stacktrace:
#0 0x55ceb1d08d9e <unknown>
#1 0x55ceb17a7fab <unknown>
#2 0x55ceb17de95a <unknown>
#3 0x55ceb17d9f5f <unknown>
#4 0x55ceb182e290 <unknown>
#5 0x55ceb181c283 <unknown>
#6 0x55ceb17e60c9 <unknown>
#7 0x55ceb17e6e78 <unknown>
#8 0x55ceb1cd4f5a <unknown>
#9 0x55ceb1cd83ae <unknown>
#10 0x55ceb1cd7e58 <unknown>
#11 0x55ceb1cd8845 <unknown>
#12 0x55ceb1cbe38b <unknown>
#13 0x55ceb1cd8bb0 <unknown>
#14 0x55ceb1ca7339 <unknown>
#15 0x55ceb1cf78b5 <unknown>
#16 0x55ceb1cf7a9b <unknown>
#17 0x55ceb1d07f15 <unknown>
#18 0x7f19bcc261f5 <unknown>

[2025-06-05T10:03:55.532+0000] {taskinstance.py:1206} INFO - Marking task as FAILED. dag_id=crawl_dmcl_tara_dag, task_id=crawl_dmcl_prices, run_id=manual__2025-06-05T09:58:44.801779+00:00, execution_date=20250605T095844, start_date=20250605T100353, end_date=20250605T100355
[2025-06-05T10:03:55.545+0000] {standard_task_runner.py:110} ERROR - Failed to execute job 171 for task crawl_dmcl_prices (Message: session not created: probably user data directory is already in use, please specify a unique value for --user-data-dir argument, or don't use --user-data-dir
Stacktrace:
#0 0x55ceb1d08d9e <unknown>
#1 0x55ceb17a7fab <unknown>
#2 0x55ceb17de95a <unknown>
#3 0x55ceb17d9f5f <unknown>
#4 0x55ceb182e290 <unknown>
#5 0x55ceb181c283 <unknown>
#6 0x55ceb17e60c9 <unknown>
#7 0x55ceb17e6e78 <unknown>
#8 0x55ceb1cd4f5a <unknown>
#9 0x55ceb1cd83ae <unknown>
#10 0x55ceb1cd7e58 <unknown>
#11 0x55ceb1cd8845 <unknown>
#12 0x55ceb1cbe38b <unknown>
#13 0x55ceb1cd8bb0 <unknown>
#14 0x55ceb1ca7339 <unknown>
#15 0x55ceb1cf78b5 <unknown>
#16 0x55ceb1cf7a9b <unknown>
#17 0x55ceb1d07f15 <unknown>
#18 0x7f19bcc261f5 <unknown>
; 110)
[2025-06-05T10:03:55.573+0000] {local_task_job_runner.py:240} INFO - Task exited with return code 1
[2025-06-05T10:03:55.590+0000] {taskinstance.py:3498} INFO - 0 downstream tasks scheduled from follow-on schedule check
[2025-06-05T10:03:55.592+0000] {local_task_job_runner.py:222} INFO - ::endgroup::
